2023-02-02 16:01:30,717 - INFO - views - views.py - User has been registred
2023-02-02 16:01:40,824 - INFO - views - views.py - Data about friends has been accepted
2023-02-02 16:01:44,645 - INFO - views - views.py - Data about friends has been accepted
2023-02-02 16:02:35,510 - INFO - views - views.py - User has been registred
2023-02-02 16:02:41,207 - INFO - views - views.py - Data about friends has been accepted
2023-02-02 16:02:44,548 - INFO - views - views.py - Data about friends has been accepted
2023-02-02 16:02:45,468 - INFO - views - views.py - Data about friends has been accepted
2023-02-02 16:02:49,127 - INFO - views - views.py - Data about friends has been accepted
2023-02-02 16:03:42,370 - INFO - views - views.py - Data about friends has been accepted
2023-02-02 16:03:43,217 - INFO - views - views.py - Data about friends has been accepted
2023-02-02 16:03:45,336 - INFO - views - views.py - Data about friends has been accepted
2023-02-02 16:03:48,342 - INFO - views - views.py - Data about friends has been accepted
2023-02-02 16:03:54,356 - INFO - views - views.py - Data about friends has been accepted
2023-02-02 16:03:57,224 - INFO - views - views.py - Data about friends has been accepted
2023-02-02 16:03:59,470 - INFO - views - views.py - Data about friends has been accepted
2023-02-02 16:04:00,689 - INFO - views - views.py - Data about friends has been accepted
2023-02-02 19:47:22,264 - INFO - views - views.py - User has got mypage
2023-02-02 19:47:41,527 - INFO - views - views.py - User has got mypage
2023-02-02 19:47:44,634 - INFO - views - views.py - User has got mypage
2023-02-02 19:48:22,668 - WARNING - log - log.py - Not Found: /favicon.ico
2023-02-02 19:48:24,154 - INFO - views - views.py - User has got mypage
2023-02-02 19:48:27,884 - INFO - views - views.py - User has got mypage
2023-02-02 19:48:32,972 - INFO - views - views.py - User has got mypage
2023-02-02 19:48:33,266 - INFO - views - views.py - User has got mypage
2023-02-02 19:48:33,575 - INFO - views - views.py - User has got mypage
2023-02-02 19:48:45,794 - INFO - views - views.py - User has got mypage
2023-02-02 19:50:00,785 - ERROR - log - log.py - Internal Server Error: /api/v1/userfriends/2
Traceback (most recent call last):
  File "C:\Users\rusil\Desktop\django\sweb\swenv\lib\site-packages\django\core\handlers\exception.py", line 55, in inner
    response = get_response(request)
  File "C:\Users\rusil\Desktop\django\sweb\swenv\lib\site-packages\django\core\handlers\base.py", line 197, in _get_response
    response = wrapped_callback(request, *callback_args, **callback_kwargs)
  File "C:\Users\rusil\Desktop\django\sweb\swenv\lib\site-packages\django\views\decorators\csrf.py", line 54, in wrapped_view
    return view_func(*args, **kwargs)
  File "C:\Users\rusil\Desktop\django\sweb\swenv\lib\site-packages\django\views\generic\base.py", line 103, in view
    return self.dispatch(request, *args, **kwargs)
  File "C:\Users\rusil\Desktop\django\sweb\swenv\lib\site-packages\rest_framework\views.py", line 509, in dispatch
    response = self.handle_exception(exc)
  File "C:\Users\rusil\Desktop\django\sweb\swenv\lib\site-packages\rest_framework\views.py", line 469, in handle_exception
    self.raise_uncaught_exception(exc)
  File "C:\Users\rusil\Desktop\django\sweb\swenv\lib\site-packages\rest_framework\views.py", line 480, in raise_uncaught_exception
    raise exc
  File "C:\Users\rusil\Desktop\django\sweb\swenv\lib\site-packages\rest_framework\views.py", line 506, in dispatch
    response = handler(request, *args, **kwargs)
  File "C:\Users\rusil\Desktop\django\sweb\swenv\lib\site-packages\rest_framework\generics.py", line 252, in get
    return self.retrieve(request, *args, **kwargs)
  File "C:\Users\rusil\Desktop\django\sweb\swenv\lib\site-packages\rest_framework\mixins.py", line 54, in retrieve
    instance = self.get_object()
  File "C:\Users\rusil\Desktop\django\sweb\socialweb\users\api.py", line 67, in get_object
    return UserModel.objects.get(pk=self.kwargs.get('pk'))
  File "C:\Users\rusil\Desktop\django\sweb\swenv\lib\site-packages\django\db\models\manager.py", line 85, in manager_method
    return getattr(self.get_queryset(), name)(*args, **kwargs)
  File "C:\Users\rusil\Desktop\django\sweb\swenv\lib\site-packages\django\db\models\query.py", line 650, in get
    raise self.model.DoesNotExist(
users.models.UserModel.DoesNotExist: UserModel matching query does not exist.
2023-02-02 19:50:04,049 - ERROR - log - log.py - Internal Server Error: /api/v1/userfriends/2
Traceback (most recent call last):
  File "C:\Users\rusil\Desktop\django\sweb\swenv\lib\site-packages\django\core\handlers\exception.py", line 55, in inner
    response = get_response(request)
  File "C:\Users\rusil\Desktop\django\sweb\swenv\lib\site-packages\django\core\handlers\base.py", line 197, in _get_response
    response = wrapped_callback(request, *callback_args, **callback_kwargs)
  File "C:\Users\rusil\Desktop\django\sweb\swenv\lib\site-packages\django\views\decorators\csrf.py", line 54, in wrapped_view
    return view_func(*args, **kwargs)
  File "C:\Users\rusil\Desktop\django\sweb\swenv\lib\site-packages\django\views\generic\base.py", line 103, in view
    return self.dispatch(request, *args, **kwargs)
  File "C:\Users\rusil\Desktop\django\sweb\swenv\lib\site-packages\rest_framework\views.py", line 509, in dispatch
    response = self.handle_exception(exc)
  File "C:\Users\rusil\Desktop\django\sweb\swenv\lib\site-packages\rest_framework\views.py", line 469, in handle_exception
    self.raise_uncaught_exception(exc)
  File "C:\Users\rusil\Desktop\django\sweb\swenv\lib\site-packages\rest_framework\views.py", line 480, in raise_uncaught_exception
    raise exc
  File "C:\Users\rusil\Desktop\django\sweb\swenv\lib\site-packages\rest_framework\views.py", line 506, in dispatch
    response = handler(request, *args, **kwargs)
  File "C:\Users\rusil\Desktop\django\sweb\swenv\lib\site-packages\rest_framework\generics.py", line 252, in get
    return self.retrieve(request, *args, **kwargs)
  File "C:\Users\rusil\Desktop\django\sweb\swenv\lib\site-packages\rest_framework\mixins.py", line 54, in retrieve
    instance = self.get_object()
  File "C:\Users\rusil\Desktop\django\sweb\socialweb\users\api.py", line 67, in get_object
    return UserModel.objects.get(pk=self.kwargs.get('pk'))
  File "C:\Users\rusil\Desktop\django\sweb\swenv\lib\site-packages\django\db\models\manager.py", line 85, in manager_method
    return getattr(self.get_queryset(), name)(*args, **kwargs)
  File "C:\Users\rusil\Desktop\django\sweb\swenv\lib\site-packages\django\db\models\query.py", line 650, in get
    raise self.model.DoesNotExist(
users.models.UserModel.DoesNotExist: UserModel matching query does not exist.
2023-02-02 19:50:05,504 - ERROR - log - log.py - Internal Server Error: /api/v1/userfriends/2
Traceback (most recent call last):
  File "C:\Users\rusil\Desktop\django\sweb\swenv\lib\site-packages\django\core\handlers\exception.py", line 55, in inner
    response = get_response(request)
  File "C:\Users\rusil\Desktop\django\sweb\swenv\lib\site-packages\django\core\handlers\base.py", line 197, in _get_response
    response = wrapped_callback(request, *callback_args, **callback_kwargs)
  File "C:\Users\rusil\Desktop\django\sweb\swenv\lib\site-packages\django\views\decorators\csrf.py", line 54, in wrapped_view
    return view_func(*args, **kwargs)
  File "C:\Users\rusil\Desktop\django\sweb\swenv\lib\site-packages\django\views\generic\base.py", line 103, in view
    return self.dispatch(request, *args, **kwargs)
  File "C:\Users\rusil\Desktop\django\sweb\swenv\lib\site-packages\rest_framework\views.py", line 509, in dispatch
    response = self.handle_exception(exc)
  File "C:\Users\rusil\Desktop\django\sweb\swenv\lib\site-packages\rest_framework\views.py", line 469, in handle_exception
    self.raise_uncaught_exception(exc)
  File "C:\Users\rusil\Desktop\django\sweb\swenv\lib\site-packages\rest_framework\views.py", line 480, in raise_uncaught_exception
    raise exc
  File "C:\Users\rusil\Desktop\django\sweb\swenv\lib\site-packages\rest_framework\views.py", line 506, in dispatch
    response = handler(request, *args, **kwargs)
  File "C:\Users\rusil\Desktop\django\sweb\swenv\lib\site-packages\rest_framework\generics.py", line 252, in get
    return self.retrieve(request, *args, **kwargs)
  File "C:\Users\rusil\Desktop\django\sweb\swenv\lib\site-packages\rest_framework\mixins.py", line 54, in retrieve
    instance = self.get_object()
  File "C:\Users\rusil\Desktop\django\sweb\socialweb\users\api.py", line 67, in get_object
    return UserModel.objects.get(pk=self.kwargs.get('pk'))
  File "C:\Users\rusil\Desktop\django\sweb\swenv\lib\site-packages\django\db\models\manager.py", line 85, in manager_method
    return getattr(self.get_queryset(), name)(*args, **kwargs)
  File "C:\Users\rusil\Desktop\django\sweb\swenv\lib\site-packages\django\db\models\query.py", line 650, in get
    raise self.model.DoesNotExist(
users.models.UserModel.DoesNotExist: UserModel matching query does not exist.
2023-02-02 19:50:07,763 - ERROR - log - log.py - Internal Server Error: /api/v1/userfriends/2
Traceback (most recent call last):
  File "C:\Users\rusil\Desktop\django\sweb\swenv\lib\site-packages\django\core\handlers\exception.py", line 55, in inner
    response = get_response(request)
  File "C:\Users\rusil\Desktop\django\sweb\swenv\lib\site-packages\django\core\handlers\base.py", line 197, in _get_response
    response = wrapped_callback(request, *callback_args, **callback_kwargs)
  File "C:\Users\rusil\Desktop\django\sweb\swenv\lib\site-packages\django\views\decorators\csrf.py", line 54, in wrapped_view
    return view_func(*args, **kwargs)
  File "C:\Users\rusil\Desktop\django\sweb\swenv\lib\site-packages\django\views\generic\base.py", line 103, in view
    return self.dispatch(request, *args, **kwargs)
  File "C:\Users\rusil\Desktop\django\sweb\swenv\lib\site-packages\rest_framework\views.py", line 509, in dispatch
    response = self.handle_exception(exc)
  File "C:\Users\rusil\Desktop\django\sweb\swenv\lib\site-packages\rest_framework\views.py", line 469, in handle_exception
    self.raise_uncaught_exception(exc)
  File "C:\Users\rusil\Desktop\django\sweb\swenv\lib\site-packages\rest_framework\views.py", line 480, in raise_uncaught_exception
    raise exc
  File "C:\Users\rusil\Desktop\django\sweb\swenv\lib\site-packages\rest_framework\views.py", line 506, in dispatch
    response = handler(request, *args, **kwargs)
  File "C:\Users\rusil\Desktop\django\sweb\swenv\lib\site-packages\rest_framework\generics.py", line 252, in get
    return self.retrieve(request, *args, **kwargs)
  File "C:\Users\rusil\Desktop\django\sweb\swenv\lib\site-packages\rest_framework\mixins.py", line 54, in retrieve
    instance = self.get_object()
  File "C:\Users\rusil\Desktop\django\sweb\socialweb\users\api.py", line 67, in get_object
    return UserModel.objects.get(pk=self.kwargs.get('pk'))
  File "C:\Users\rusil\Desktop\django\sweb\swenv\lib\site-packages\django\db\models\manager.py", line 85, in manager_method
    return getattr(self.get_queryset(), name)(*args, **kwargs)
  File "C:\Users\rusil\Desktop\django\sweb\swenv\lib\site-packages\django\db\models\query.py", line 650, in get
    raise self.model.DoesNotExist(
users.models.UserModel.DoesNotExist: UserModel matching query does not exist.
2023-02-02 19:50:11,217 - ERROR - log - log.py - Internal Server Error: /api/v1/userfriends/1
Traceback (most recent call last):
  File "C:\Users\rusil\Desktop\django\sweb\swenv\lib\site-packages\django\core\handlers\exception.py", line 55, in inner
    response = get_response(request)
  File "C:\Users\rusil\Desktop\django\sweb\swenv\lib\site-packages\django\core\handlers\base.py", line 197, in _get_response
    response = wrapped_callback(request, *callback_args, **callback_kwargs)
  File "C:\Users\rusil\Desktop\django\sweb\swenv\lib\site-packages\django\views\decorators\csrf.py", line 54, in wrapped_view
    return view_func(*args, **kwargs)
  File "C:\Users\rusil\Desktop\django\sweb\swenv\lib\site-packages\django\views\generic\base.py", line 103, in view
    return self.dispatch(request, *args, **kwargs)
  File "C:\Users\rusil\Desktop\django\sweb\swenv\lib\site-packages\rest_framework\views.py", line 509, in dispatch
    response = self.handle_exception(exc)
  File "C:\Users\rusil\Desktop\django\sweb\swenv\lib\site-packages\rest_framework\views.py", line 469, in handle_exception
    self.raise_uncaught_exception(exc)
  File "C:\Users\rusil\Desktop\django\sweb\swenv\lib\site-packages\rest_framework\views.py", line 480, in raise_uncaught_exception
    raise exc
  File "C:\Users\rusil\Desktop\django\sweb\swenv\lib\site-packages\rest_framework\views.py", line 506, in dispatch
    response = handler(request, *args, **kwargs)
  File "C:\Users\rusil\Desktop\django\sweb\swenv\lib\site-packages\rest_framework\generics.py", line 252, in get
    return self.retrieve(request, *args, **kwargs)
  File "C:\Users\rusil\Desktop\django\sweb\swenv\lib\site-packages\rest_framework\mixins.py", line 54, in retrieve
    instance = self.get_object()
  File "C:\Users\rusil\Desktop\django\sweb\socialweb\users\api.py", line 67, in get_object
    return UserModel.objects.get(pk=self.kwargs.get('pk'))
  File "C:\Users\rusil\Desktop\django\sweb\swenv\lib\site-packages\django\db\models\manager.py", line 85, in manager_method
    return getattr(self.get_queryset(), name)(*args, **kwargs)
  File "C:\Users\rusil\Desktop\django\sweb\swenv\lib\site-packages\django\db\models\query.py", line 650, in get
    raise self.model.DoesNotExist(
users.models.UserModel.DoesNotExist: UserModel matching query does not exist.
2023-02-02 19:50:11,853 - ERROR - log - log.py - Internal Server Error: /api/v1/userfriends/1
Traceback (most recent call last):
  File "C:\Users\rusil\Desktop\django\sweb\swenv\lib\site-packages\django\core\handlers\exception.py", line 55, in inner
    response = get_response(request)
  File "C:\Users\rusil\Desktop\django\sweb\swenv\lib\site-packages\django\core\handlers\base.py", line 197, in _get_response
    response = wrapped_callback(request, *callback_args, **callback_kwargs)
  File "C:\Users\rusil\Desktop\django\sweb\swenv\lib\site-packages\django\views\decorators\csrf.py", line 54, in wrapped_view
    return view_func(*args, **kwargs)
  File "C:\Users\rusil\Desktop\django\sweb\swenv\lib\site-packages\django\views\generic\base.py", line 103, in view
    return self.dispatch(request, *args, **kwargs)
  File "C:\Users\rusil\Desktop\django\sweb\swenv\lib\site-packages\rest_framework\views.py", line 509, in dispatch
    response = self.handle_exception(exc)
  File "C:\Users\rusil\Desktop\django\sweb\swenv\lib\site-packages\rest_framework\views.py", line 469, in handle_exception
    self.raise_uncaught_exception(exc)
  File "C:\Users\rusil\Desktop\django\sweb\swenv\lib\site-packages\rest_framework\views.py", line 480, in raise_uncaught_exception
    raise exc
  File "C:\Users\rusil\Desktop\django\sweb\swenv\lib\site-packages\rest_framework\views.py", line 506, in dispatch
    response = handler(request, *args, **kwargs)
  File "C:\Users\rusil\Desktop\django\sweb\swenv\lib\site-packages\rest_framework\generics.py", line 252, in get
    return self.retrieve(request, *args, **kwargs)
  File "C:\Users\rusil\Desktop\django\sweb\swenv\lib\site-packages\rest_framework\mixins.py", line 54, in retrieve
    instance = self.get_object()
  File "C:\Users\rusil\Desktop\django\sweb\socialweb\users\api.py", line 67, in get_object
    return UserModel.objects.get(pk=self.kwargs.get('pk'))
  File "C:\Users\rusil\Desktop\django\sweb\swenv\lib\site-packages\django\db\models\manager.py", line 85, in manager_method
    return getattr(self.get_queryset(), name)(*args, **kwargs)
  File "C:\Users\rusil\Desktop\django\sweb\swenv\lib\site-packages\django\db\models\query.py", line 650, in get
    raise self.model.DoesNotExist(
users.models.UserModel.DoesNotExist: UserModel matching query does not exist.
2023-02-02 19:50:25,084 - ERROR - log - log.py - Internal Server Error: /api/v1/userfriends/7
Traceback (most recent call last):
  File "C:\Users\rusil\Desktop\django\sweb\swenv\lib\site-packages\django\core\handlers\exception.py", line 55, in inner
    response = get_response(request)
  File "C:\Users\rusil\Desktop\django\sweb\swenv\lib\site-packages\django\core\handlers\base.py", line 197, in _get_response
    response = wrapped_callback(request, *callback_args, **callback_kwargs)
  File "C:\Users\rusil\Desktop\django\sweb\swenv\lib\site-packages\django\views\decorators\csrf.py", line 54, in wrapped_view
    return view_func(*args, **kwargs)
  File "C:\Users\rusil\Desktop\django\sweb\swenv\lib\site-packages\django\views\generic\base.py", line 103, in view
    return self.dispatch(request, *args, **kwargs)
  File "C:\Users\rusil\Desktop\django\sweb\swenv\lib\site-packages\rest_framework\views.py", line 509, in dispatch
    response = self.handle_exception(exc)
  File "C:\Users\rusil\Desktop\django\sweb\swenv\lib\site-packages\rest_framework\views.py", line 469, in handle_exception
    self.raise_uncaught_exception(exc)
  File "C:\Users\rusil\Desktop\django\sweb\swenv\lib\site-packages\rest_framework\views.py", line 480, in raise_uncaught_exception
    raise exc
  File "C:\Users\rusil\Desktop\django\sweb\swenv\lib\site-packages\rest_framework\views.py", line 506, in dispatch
    response = handler(request, *args, **kwargs)
  File "C:\Users\rusil\Desktop\django\sweb\swenv\lib\site-packages\rest_framework\generics.py", line 252, in get
    return self.retrieve(request, *args, **kwargs)
  File "C:\Users\rusil\Desktop\django\sweb\swenv\lib\site-packages\rest_framework\mixins.py", line 54, in retrieve
    instance = self.get_object()
  File "C:\Users\rusil\Desktop\django\sweb\socialweb\users\api.py", line 67, in get_object
    return UserModel.objects.get(pk=self.kwargs.get('pk'))
  File "C:\Users\rusil\Desktop\django\sweb\swenv\lib\site-packages\django\db\models\manager.py", line 85, in manager_method
    return getattr(self.get_queryset(), name)(*args, **kwargs)
  File "C:\Users\rusil\Desktop\django\sweb\swenv\lib\site-packages\django\db\models\query.py", line 650, in get
    raise self.model.DoesNotExist(
users.models.UserModel.DoesNotExist: UserModel matching query does not exist.
2023-02-02 19:58:23,162 - WARNING - log - log.py - Method Not Allowed: /api/v1/friendshipdelete/6
2023-02-02 19:58:28,682 - WARNING - log - log.py - Method Not Allowed: /api/v1/friendshipdelete/45
2023-02-02 19:58:30,244 - WARNING - log - log.py - Method Not Allowed: /api/v1/friendshipdelete/5
2023-02-02 19:58:31,759 - WARNING - log - log.py - Method Not Allowed: /api/v1/friendshipdelete/4
2023-02-02 19:58:36,092 - WARNING - log - log.py - Method Not Allowed: /api/v1/friendshipdelete/1
2023-02-02 19:58:38,775 - WARNING - log - log.py - Method Not Allowed: /api/v1/friendshipdelete/2
2023-02-02 19:58:40,514 - WARNING - log - log.py - Method Not Allowed: /api/v1/friendshipdelete/3
2023-02-02 19:58:42,136 - WARNING - log - log.py - Method Not Allowed: /api/v1/friendshipdelete/4
2023-02-02 19:58:43,841 - WARNING - log - log.py - Method Not Allowed: /api/v1/friendshipdelete/5
2023-02-02 19:58:45,213 - WARNING - log - log.py - Method Not Allowed: /api/v1/friendshipdelete/6
2023-02-02 19:58:46,893 - WARNING - log - log.py - Method Not Allowed: /api/v1/friendshipdelete/7
2023-02-02 19:59:02,562 - WARNING - log - log.py - Method Not Allowed: /api/v1/friendshipdelete/7
2023-02-02 19:59:07,338 - WARNING - log - log.py - Method Not Allowed: /api/v1/friendshipdelete/7
2023-02-02 19:59:12,150 - WARNING - log - log.py - Method Not Allowed: /api/v1/friendshipdelete/4
2023-02-02 19:59:14,019 - WARNING - log - log.py - Method Not Allowed: /api/v1/friendshipdelete/4
2023-02-02 19:59:51,697 - WARNING - log - log.py - Method Not Allowed: /api/v1/friendshipdelete/4
2023-02-02 19:59:54,296 - WARNING - log - log.py - Method Not Allowed: /api/v1/friendshipdelete/5
2023-02-02 19:59:56,729 - WARNING - log - log.py - Method Not Allowed: /api/v1/friendshipdelete/6
2023-02-02 20:00:05,554 - WARNING - log - log.py - Method Not Allowed: /api/v1/friendshipdelete/6
2023-02-02 20:00:12,418 - WARNING - log - log.py - Method Not Allowed: /api/v1/friendshipdelete/5
2023-02-02 20:00:12,602 - WARNING - log - log.py - Method Not Allowed: /api/v1/friendshipdelete/5
2023-02-02 20:00:14,307 - WARNING - log - log.py - Method Not Allowed: /api/v1/friendshipdelete/3
2023-02-02 20:00:16,028 - WARNING - log - log.py - Method Not Allowed: /api/v1/friendshipdelete/4
2023-02-02 20:00:26,761 - WARNING - log - log.py - Method Not Allowed: /api/v1/friendshipdelete/2
2023-02-02 20:00:29,264 - WARNING - log - log.py - Method Not Allowed: /api/v1/friendshipdelete/3
2023-02-02 20:00:35,500 - WARNING - log - log.py - Method Not Allowed: /api/v1/friendshipdelete/5
2023-02-02 20:00:35,580 - WARNING - log - log.py - Method Not Allowed: /api/v1/friendshipdelete/5
2023-02-02 20:00:37,204 - WARNING - log - log.py - Method Not Allowed: /api/v1/friendshipdelete/6
2023-02-02 20:00:37,269 - WARNING - log - log.py - Method Not Allowed: /api/v1/friendshipdelete/6
2023-02-02 20:00:55,792 - WARNING - log - log.py - Method Not Allowed: /api/v1/friendshipdelete/6
2023-02-02 20:00:57,554 - WARNING - log - log.py - Method Not Allowed: /api/v1/friendshipdelete/3
2023-02-02 20:00:57,647 - WARNING - log - log.py - Method Not Allowed: /api/v1/friendshipdelete/3
2023-02-02 20:00:59,209 - WARNING - log - log.py - Method Not Allowed: /api/v1/friendshipdelete/4
2023-02-02 20:01:00,839 - WARNING - log - log.py - Method Not Allowed: /api/v1/friendshipdelete/5
2023-02-02 20:01:00,893 - WARNING - log - log.py - Method Not Allowed: /api/v1/friendshipdelete/5
2023-02-02 20:01:03,991 - WARNING - log - log.py - Method Not Allowed: /api/v1/friendshipdelete/6
2023-02-02 20:01:04,180 - WARNING - log - log.py - Method Not Allowed: /api/v1/friendshipdelete/6
2023-02-02 20:11:19,384 - WARNING - log - log.py - Not Found: /favicon.ico
2023-02-02 20:11:26,501 - INFO - views - views.py - Data about friends has been accepted
2023-02-02 20:11:32,792 - INFO - views - views.py - Data about friends has been accepted
2023-02-02 20:12:00,132 - INFO - views - views.py - Data about friends has been accepted
2023-02-02 20:12:12,191 - INFO - views - views.py - Data about friends has been accepted
2023-02-02 20:12:21,727 - INFO - views - views.py - Data about friends has been accepted
2023-02-02 20:14:44,533 - INFO - views - views.py - Data about friends has been accepted
2023-02-02 20:14:52,962 - INFO - views - views.py - Data about friends has been accepted
2023-02-02 20:14:59,421 - INFO - views - views.py - Data about friends has been accepted
2023-02-02 20:15:06,484 - INFO - views - views.py - Data about friends has been accepted
2023-02-02 20:25:07,274 - ERROR - log - log.py - Internal Server Error: /api/v1/user
Traceback (most recent call last):
  File "C:\Users\rusil\Desktop\django\sweb\swenv\lib\site-packages\django\core\handlers\exception.py", line 55, in inner
    response = get_response(request)
  File "C:\Users\rusil\Desktop\django\sweb\swenv\lib\site-packages\django\core\handlers\base.py", line 220, in _get_response
    response = response.render()
  File "C:\Users\rusil\Desktop\django\sweb\swenv\lib\site-packages\django\template\response.py", line 114, in render
    self.content = self.rendered_content
  File "C:\Users\rusil\Desktop\django\sweb\swenv\lib\site-packages\rest_framework\response.py", line 70, in rendered_content
    ret = renderer.render(self.data, accepted_media_type, context)
  File "C:\Users\rusil\Desktop\django\sweb\swenv\lib\site-packages\rest_framework\renderers.py", line 723, in render
    context = self.get_context(data, accepted_media_type, renderer_context)
  File "C:\Users\rusil\Desktop\django\sweb\swenv\lib\site-packages\rest_framework\renderers.py", line 679, in get_context
    'content': self.get_content(renderer, data, accepted_media_type, renderer_context),
  File "C:\Users\rusil\Desktop\django\sweb\swenv\lib\site-packages\rest_framework\renderers.py", line 412, in get_content
    content = renderer.render(data, accepted_media_type, renderer_context)
  File "C:\Users\rusil\Desktop\django\sweb\swenv\lib\site-packages\rest_framework\renderers.py", line 99, in render
    ret = json.dumps(
  File "C:\Users\rusil\Desktop\django\sweb\swenv\lib\site-packages\rest_framework\utils\json.py", line 25, in dumps
    return json.dumps(*args, **kwargs)
  File "C:\Users\rusil\AppData\Local\Programs\Python\Python310\lib\json\__init__.py", line 238, in dumps
    **kw).encode(obj)
  File "C:\Users\rusil\AppData\Local\Programs\Python\Python310\lib\json\encoder.py", line 201, in encode
    chunks = list(chunks)
  File "C:\Users\rusil\AppData\Local\Programs\Python\Python310\lib\json\encoder.py", line 429, in _iterencode
    yield from _iterencode_list(o, _current_indent_level)
  File "C:\Users\rusil\AppData\Local\Programs\Python\Python310\lib\json\encoder.py", line 325, in _iterencode_list
    yield from chunks
  File "C:\Users\rusil\AppData\Local\Programs\Python\Python310\lib\json\encoder.py", line 405, in _iterencode_dict
    yield from chunks
  File "C:\Users\rusil\AppData\Local\Programs\Python\Python310\lib\json\encoder.py", line 438, in _iterencode
    o = _default(o)
  File "C:\Users\rusil\Desktop\django\sweb\swenv\lib\site-packages\rest_framework\utils\encoders.py", line 67, in default
    return super().default(obj)
  File "C:\Users\rusil\AppData\Local\Programs\Python\Python310\lib\json\encoder.py", line 179, in default
    raise TypeError(f'Object of type {o.__class__.__name__} '
TypeError: Object of type Country is not JSON serializable
2023-02-02 20:25:23,360 - ERROR - log - log.py - Internal Server Error: /api/v1/user
Traceback (most recent call last):
  File "C:\Users\rusil\Desktop\django\sweb\swenv\lib\site-packages\django\core\handlers\exception.py", line 55, in inner
    response = get_response(request)
  File "C:\Users\rusil\Desktop\django\sweb\swenv\lib\site-packages\django\core\handlers\base.py", line 220, in _get_response
    response = response.render()
  File "C:\Users\rusil\Desktop\django\sweb\swenv\lib\site-packages\django\template\response.py", line 114, in render
    self.content = self.rendered_content
  File "C:\Users\rusil\Desktop\django\sweb\swenv\lib\site-packages\rest_framework\response.py", line 70, in rendered_content
    ret = renderer.render(self.data, accepted_media_type, context)
  File "C:\Users\rusil\Desktop\django\sweb\swenv\lib\site-packages\rest_framework\renderers.py", line 723, in render
    context = self.get_context(data, accepted_media_type, renderer_context)
  File "C:\Users\rusil\Desktop\django\sweb\swenv\lib\site-packages\rest_framework\renderers.py", line 679, in get_context
    'content': self.get_content(renderer, data, accepted_media_type, renderer_context),
  File "C:\Users\rusil\Desktop\django\sweb\swenv\lib\site-packages\rest_framework\renderers.py", line 412, in get_content
    content = renderer.render(data, accepted_media_type, renderer_context)
  File "C:\Users\rusil\Desktop\django\sweb\swenv\lib\site-packages\rest_framework\renderers.py", line 99, in render
    ret = json.dumps(
  File "C:\Users\rusil\Desktop\django\sweb\swenv\lib\site-packages\rest_framework\utils\json.py", line 25, in dumps
    return json.dumps(*args, **kwargs)
  File "C:\Users\rusil\AppData\Local\Programs\Python\Python310\lib\json\__init__.py", line 238, in dumps
    **kw).encode(obj)
  File "C:\Users\rusil\AppData\Local\Programs\Python\Python310\lib\json\encoder.py", line 201, in encode
    chunks = list(chunks)
  File "C:\Users\rusil\AppData\Local\Programs\Python\Python310\lib\json\encoder.py", line 429, in _iterencode
    yield from _iterencode_list(o, _current_indent_level)
  File "C:\Users\rusil\AppData\Local\Programs\Python\Python310\lib\json\encoder.py", line 325, in _iterencode_list
    yield from chunks
  File "C:\Users\rusil\AppData\Local\Programs\Python\Python310\lib\json\encoder.py", line 405, in _iterencode_dict
    yield from chunks
  File "C:\Users\rusil\AppData\Local\Programs\Python\Python310\lib\json\encoder.py", line 438, in _iterencode
    o = _default(o)
  File "C:\Users\rusil\Desktop\django\sweb\swenv\lib\site-packages\rest_framework\utils\encoders.py", line 67, in default
    return super().default(obj)
  File "C:\Users\rusil\AppData\Local\Programs\Python\Python310\lib\json\encoder.py", line 179, in default
    raise TypeError(f'Object of type {o.__class__.__name__} '
TypeError: Object of type Country is not JSON serializable
2023-02-02 20:26:47,135 - ERROR - log - log.py - Internal Server Error: /postphoto/3
Traceback (most recent call last):
  File "C:\Users\rusil\Desktop\django\sweb\swenv\lib\site-packages\django\db\models\fields\__init__.py", line 2018, in get_prep_value
    return int(value)
TypeError: int() argument must be a string, a bytes-like object or a real number, not 'SimpleLazyObject'

The above exception was the direct cause of the following exception:

Traceback (most recent call last):
  File "C:\Users\rusil\Desktop\django\sweb\swenv\lib\site-packages\django\core\handlers\exception.py", line 55, in inner
    response = get_response(request)
  File "C:\Users\rusil\Desktop\django\sweb\swenv\lib\site-packages\django\core\handlers\base.py", line 197, in _get_response
    response = wrapped_callback(request, *callback_args, **callback_kwargs)
  File "C:\Users\rusil\Desktop\django\sweb\swenv\lib\site-packages\django\views\generic\base.py", line 103, in view
    return self.dispatch(request, *args, **kwargs)
  File "C:\Users\rusil\Desktop\django\sweb\swenv\lib\site-packages\django\views\generic\base.py", line 142, in dispatch
    return handler(request, *args, **kwargs)
  File "C:\Users\rusil\Desktop\django\sweb\swenv\lib\site-packages\django\views\generic\edit.py", line 180, in get
    return super().get(request, *args, **kwargs)
  File "C:\Users\rusil\Desktop\django\sweb\swenv\lib\site-packages\django\views\generic\edit.py", line 144, in get
    return self.render_to_response(self.get_context_data())
  File "C:\Users\rusil\Desktop\django\sweb\socialweb\users\views.py", line 179, in get_context_data
    context['images']=PhotoModel.objects.filter(user=self.request.user)
  File "C:\Users\rusil\Desktop\django\sweb\swenv\lib\site-packages\django\db\models\manager.py", line 85, in manager_method
    return getattr(self.get_queryset(), name)(*args, **kwargs)
  File "C:\Users\rusil\Desktop\django\sweb\swenv\lib\site-packages\django\db\models\query.py", line 1421, in filter
    return self._filter_or_exclude(False, args, kwargs)
  File "C:\Users\rusil\Desktop\django\sweb\swenv\lib\site-packages\django\db\models\query.py", line 1439, in _filter_or_exclude
    clone._filter_or_exclude_inplace(negate, args, kwargs)
  File "C:\Users\rusil\Desktop\django\sweb\swenv\lib\site-packages\django\db\models\query.py", line 1446, in _filter_or_exclude_inplace
    self._query.add_q(Q(*args, **kwargs))
  File "C:\Users\rusil\Desktop\django\sweb\swenv\lib\site-packages\django\db\models\sql\query.py", line 1532, in add_q
    clause, _ = self._add_q(q_object, self.used_aliases)
  File "C:\Users\rusil\Desktop\django\sweb\swenv\lib\site-packages\django\db\models\sql\query.py", line 1562, in _add_q
    child_clause, needed_inner = self.build_filter(
  File "C:\Users\rusil\Desktop\django\sweb\swenv\lib\site-packages\django\db\models\sql\query.py", line 1478, in build_filter
    condition = self.build_lookup(lookups, col, value)
  File "C:\Users\rusil\Desktop\django\sweb\swenv\lib\site-packages\django\db\models\sql\query.py", line 1303, in build_lookup
    lookup = lookup_class(lhs, rhs)
  File "C:\Users\rusil\Desktop\django\sweb\swenv\lib\site-packages\django\db\models\lookups.py", line 27, in __init__
    self.rhs = self.get_prep_lookup()
  File "C:\Users\rusil\Desktop\django\sweb\swenv\lib\site-packages\django\db\models\fields\related_lookups.py", line 166, in get_prep_lookup
    self.rhs = target_field.get_prep_value(self.rhs)
  File "C:\Users\rusil\Desktop\django\sweb\swenv\lib\site-packages\django\db\models\fields\__init__.py", line 2020, in get_prep_value
    raise e.__class__(
TypeError: Field 'id' expected a number but got <SimpleLazyObject: <django.contrib.auth.models.AnonymousUser object at 0x00000214AF570130>>.
2023-02-02 20:31:52,737 - ERROR - log - log.py - Internal Server Error: /api/v1/user
Traceback (most recent call last):
  File "C:\Users\rusil\Desktop\django\sweb\swenv\lib\site-packages\django\core\handlers\exception.py", line 55, in inner
    response = get_response(request)
  File "C:\Users\rusil\Desktop\django\sweb\swenv\lib\site-packages\django\core\handlers\base.py", line 197, in _get_response
    response = wrapped_callback(request, *callback_args, **callback_kwargs)
  File "C:\Users\rusil\Desktop\django\sweb\swenv\lib\site-packages\django\views\decorators\csrf.py", line 54, in wrapped_view
    return view_func(*args, **kwargs)
  File "C:\Users\rusil\Desktop\django\sweb\swenv\lib\site-packages\django\views\generic\base.py", line 103, in view
    return self.dispatch(request, *args, **kwargs)
  File "C:\Users\rusil\Desktop\django\sweb\swenv\lib\site-packages\rest_framework\views.py", line 509, in dispatch
    response = self.handle_exception(exc)
  File "C:\Users\rusil\Desktop\django\sweb\swenv\lib\site-packages\rest_framework\views.py", line 469, in handle_exception
    self.raise_uncaught_exception(exc)
  File "C:\Users\rusil\Desktop\django\sweb\swenv\lib\site-packages\rest_framework\views.py", line 480, in raise_uncaught_exception
    raise exc
  File "C:\Users\rusil\Desktop\django\sweb\swenv\lib\site-packages\rest_framework\views.py", line 506, in dispatch
    response = handler(request, *args, **kwargs)
  File "C:\Users\rusil\Desktop\django\sweb\socialweb\users\api.py", line 27, in post
    serializer.save()
  File "C:\Users\rusil\Desktop\django\sweb\socialweb\users\serializers.py", line 22, in save
    country=self.validated_data['country'],
KeyError: 'country'
